16-12-2022 13:59:58 | INFO | Snowflake Connector for Python Version: 2.9.0, Python Version: 3.10.0, Platform: Windows-10-10.0.19044-SP0
16-12-2022 13:59:58 | INFO | This connection is in OCSP Fail Open Mode. TLS Certificates would be checked for validity and revocation status. Any other Certificate Revocation related exceptions or OCSP Responder failures would be disregarded in favor of connectivity.
16-12-2022 13:59:58 | INFO | Setting use_openssl_only mode to False
16-12-2022 13:59:58 | WARNING | Retrying (Retry(total=0, connect=None, read=None, redirect=None, status=None)) after connection broken by 'NewConnectionError('<snowflake.connector.vendored.urllib3.connection.HTTPSConnection object at 0x000001914F0E4730>: Failed to establish a new connection: [Errno 11001] getaddrinfo failed')': /session/v1/login-request?request_id=5367a84c-2ced-4e10-b4b0-13dca0f58ca0&databaseName=%3CYOUR+SNOWFLAKE+DATABASE%3E&schemaName=%3CYOUR+SNOWFLAKE+SCHEMA%3E&warehouse=%3CYOUR+SNOWFLAKE+DW+NAME%3E&request_guid=fc0190d6-ee43-4972-a01d-0660a7a5769e
16-12-2022 14:00:00 | WARNING | Retrying (Retry(total=0, connect=None, read=None, redirect=None, status=None)) after connection broken by 'NewConnectionError('<snowflake.connector.vendored.urllib3.connection.HTTPSConnection object at 0x000001914F0E5030>: Failed to establish a new connection: [Errno 11001] getaddrinfo failed')': /session/v1/login-request?request_id=4ca66eae-e46e-46bb-ba84-ac6aa2feb66e&databaseName=%3CYOUR+SNOWFLAKE+DATABASE%3E&schemaName=%3CYOUR+SNOWFLAKE+SCHEMA%3E&warehouse=%3CYOUR+SNOWFLAKE+DW+NAME%3E&request_guid=01b046bd-8b32-4ac8-ab8b-8b5092ecbf80
16-12-2022 14:00:00 | INFO | closed
