16-12-2022 12:30:28 | INFO | Snowflake Connector for Python Version: 2.9.0, Python Version: 3.10.0, Platform: Windows-10-10.0.19044-SP0
16-12-2022 12:30:28 | INFO | This connection is in OCSP Fail Open Mode. TLS Certificates would be checked for validity and revocation status. Any other Certificate Revocation related exceptions or OCSP Responder failures would be disregarded in favor of connectivity.
16-12-2022 12:30:28 | INFO | Setting use_openssl_only mode to False
16-12-2022 12:30:28 | WARNING | Retrying (Retry(total=0, connect=None, read=None, redirect=None, status=None)) after connection broken by 'NewConnectionError('<snowflake.connector.vendored.urllib3.connection.HTTPSConnection object at 0x000002CB1C49C880>: Failed to establish a new connection: [Errno 11001] getaddrinfo failed')': /session/v1/login-request?request_id=1fa56208-b728-4fe9-b7c3-b39a17f0c118&databaseName=%3CYOUR+SNOWFLAKE+DATABASE%3E&schemaName=%3CYOUR+SNOWFLAKE+SCHEMA%3E&warehouse=%3CYOUR+SNOWFLAKE+DW+NAME%3E&request_guid=0c85a4a8-cb17-4a30-a6aa-36bc10ad4902
16-12-2022 12:30:31 | WARNING | Retrying (Retry(total=0, connect=None, read=None, redirect=None, status=None)) after connection broken by 'NewConnectionError('<snowflake.connector.vendored.urllib3.connection.HTTPSConnection object at 0x000002CB1C49D180>: Failed to establish a new connection: [Errno 11001] getaddrinfo failed')': /session/v1/login-request?request_id=8166d96e-e1b8-4f38-9e27-63b3195beff2&databaseName=%3CYOUR+SNOWFLAKE+DATABASE%3E&schemaName=%3CYOUR+SNOWFLAKE+SCHEMA%3E&warehouse=%3CYOUR+SNOWFLAKE+DW+NAME%3E&request_guid=f00bdf91-792f-48ac-ad06-ded3494f303b
16-12-2022 12:30:31 | INFO | closed
