16-12-2022 14:02:44 | INFO | Snowflake Connector for Python Version: 2.9.0, Python Version: 3.10.0, Platform: Windows-10-10.0.19044-SP0
16-12-2022 14:02:44 | INFO | This connection is in OCSP Fail Open Mode. TLS Certificates would be checked for validity and revocation status. Any other Certificate Revocation related exceptions or OCSP Responder failures would be disregarded in favor of connectivity.
16-12-2022 14:02:44 | INFO | Setting use_openssl_only mode to False
16-12-2022 14:02:44 | WARNING | Retrying (Retry(total=0, connect=None, read=None, redirect=None, status=None)) after connection broken by 'NewConnectionError('<snowflake.connector.vendored.urllib3.connection.HTTPSConnection object at 0x0000019D612C4700>: Failed to establish a new connection: [Errno 11001] getaddrinfo failed')': /session/v1/login-request?request_id=c652722f-e0c0-4403-8875-0d1c8f49facb&databaseName=%3CYOUR+SNOWFLAKE+DATABASE%3E&schemaName=%3CYOUR+SNOWFLAKE+SCHEMA%3E&warehouse=%3CYOUR+SNOWFLAKE+DW+NAME%3E&request_guid=b9c2811e-3e4c-4152-8867-ebe4d676a762
16-12-2022 14:02:47 | WARNING | Retrying (Retry(total=0, connect=None, read=None, redirect=None, status=None)) after connection broken by 'NewConnectionError('<snowflake.connector.vendored.urllib3.connection.HTTPSConnection object at 0x0000019D612C5000>: Failed to establish a new connection: [Errno 11001] getaddrinfo failed')': /session/v1/login-request?request_id=79817267-e7cc-46d5-9385-eb1aa211838b&databaseName=%3CYOUR+SNOWFLAKE+DATABASE%3E&schemaName=%3CYOUR+SNOWFLAKE+SCHEMA%3E&warehouse=%3CYOUR+SNOWFLAKE+DW+NAME%3E&request_guid=74771b0e-0818-465c-af25-9f9cdf67e9ee
16-12-2022 14:02:47 | ERROR | Error getting users from Snowflake: 250001: 250001: Could not connect to Snowflake backend after 0 attempt(s).Aborting
16-12-2022 14:02:47 | ERROR | Error creating user items list from Snowflake results: local variable 'curs' referenced before assignment
16-12-2022 14:02:47 | INFO | get_users_from_snowflake() completed with 0 user records
16-12-2022 14:02:47 | INFO | Snowflake Connector for Python Version: 2.9.0, Python Version: 3.10.0, Platform: Windows-10-10.0.19044-SP0
16-12-2022 14:02:47 | INFO | This connection is in OCSP Fail Open Mode. TLS Certificates would be checked for validity and revocation status. Any other Certificate Revocation related exceptions or OCSP Responder failures would be disregarded in favor of connectivity.
16-12-2022 14:02:47 | WARNING | Retrying (Retry(total=0, connect=None, read=None, redirect=None, status=None)) after connection broken by 'NewConnectionError('<snowflake.connector.vendored.urllib3.connection.HTTPSConnection object at 0x0000019D612C49D0>: Failed to establish a new connection: [Errno 11001] getaddrinfo failed')': /session/v1/login-request?request_id=bcaa0e46-1696-422b-b5de-7a92c681f647&databaseName=%3CYOUR+SNOWFLAKE+DATABASE%3E&schemaName=%3CYOUR+SNOWFLAKE+SCHEMA%3E&warehouse=%3CYOUR+SNOWFLAKE+DW+NAME%3E&request_guid=fa79e0f6-05e0-431a-8abc-7421ab2f1e3b
16-12-2022 14:02:50 | WARNING | Retrying (Retry(total=0, connect=None, read=None, redirect=None, status=None)) after connection broken by 'NewConnectionError('<snowflake.connector.vendored.urllib3.connection.HTTPSConnection object at 0x0000019D612C57B0>: Failed to establish a new connection: [Errno 11001] getaddrinfo failed')': /session/v1/login-request?request_id=6e89e38d-c71e-44a0-ae14-06059267898d&databaseName=%3CYOUR+SNOWFLAKE+DATABASE%3E&schemaName=%3CYOUR+SNOWFLAKE+SCHEMA%3E&warehouse=%3CYOUR+SNOWFLAKE+DW+NAME%3E&request_guid=f50b4653-9b3b-4b5b-9855-15546984cd5d
16-12-2022 14:02:50 | ERROR | Error getting users from Snowflake: 250001: 250001: Could not connect to Snowflake backend after 0 attempt(s).Aborting
16-12-2022 14:02:50 | ERROR | Error creating user items list from Snowflake results: local variable 'curs' referenced before assignment
16-12-2022 14:02:50 | INFO | get_users_from_snowflake() completed with 0 user records
16-12-2022 14:02:50 | INFO | closed
16-12-2022 14:02:50 | INFO | closed
